2021-02-28 23:59:48 -    ERROR - django.request - Internal Server Error: /scenario/search/1
Traceback (most recent call last):
  File "C:\Users\el\.virtualenvs\epa-dev-Ocuf8svJ\lib\site-packages\django\core\handlers\exception.py", line 47, in inner
    response = get_response(request)
  File "C:\Users\el\.virtualenvs\epa-dev-Ocuf8svJ\lib\site-packages\django\core\handlers\base.py", line 179, in _get_response
    response = wrapped_callback(request, *callback_args, **callback_kwargs)
  File "C:\Users\el\.virtualenvs\epa-dev-Ocuf8svJ\lib\site-packages\django\contrib\auth\decorators.py", line 21, in _wrapped_view
    return view_func(request, *args, **kwargs)
  File "C:\Users\el\.virtualenvs\epa-dev-Ocuf8svJ\lib\site-packages\django\views\decorators\http.py", line 40, in inner
    return func(request, *args, **kwargs)
  File "C:\Users\el\Desktop\icom_project\E-LAND\epa\projects\views.py", line 203, in scenario_search
    return render(request, 'scenario/scenario_search.html',
  File "C:\Users\el\.virtualenvs\epa-dev-Ocuf8svJ\lib\site-packages\django\shortcuts.py", line 19, in render
    content = loader.render_to_string(template_name, context, request, using=using)
  File "C:\Users\el\.virtualenvs\epa-dev-Ocuf8svJ\lib\site-packages\django\template\loader.py", line 62, in render_to_string
    return template.render(context, request)
  File "C:\Users\el\.virtualenvs\epa-dev-Ocuf8svJ\lib\site-packages\django\template\backends\django.py", line 61, in render
    return self.template.render(context)
  File "C:\Users\el\.virtualenvs\epa-dev-Ocuf8svJ\lib\site-packages\django\template\base.py", line 170, in render
    return self._render(context)
  File "C:\Users\el\.virtualenvs\epa-dev-Ocuf8svJ\lib\site-packages\django\template\base.py", line 162, in _render
    return self.nodelist.render(context)
  File "C:\Users\el\.virtualenvs\epa-dev-Ocuf8svJ\lib\site-packages\django\template\base.py", line 938, in render
    bit = node.render_annotated(context)
  File "C:\Users\el\.virtualenvs\epa-dev-Ocuf8svJ\lib\site-packages\django\template\base.py", line 905, in render_annotated
    return self.render(context)
  File "C:\Users\el\.virtualenvs\epa-dev-Ocuf8svJ\lib\site-packages\django\template\loader_tags.py", line 150, in render
    return compiled_parent._render(context)
  File "C:\Users\el\.virtualenvs\epa-dev-Ocuf8svJ\lib\site-packages\django\template\base.py", line 162, in _render
    return self.nodelist.render(context)
  File "C:\Users\el\.virtualenvs\epa-dev-Ocuf8svJ\lib\site-packages\django\template\base.py", line 938, in render
    bit = node.render_annotated(context)
  File "C:\Users\el\.virtualenvs\epa-dev-Ocuf8svJ\lib\site-packages\django\template\base.py", line 905, in render_annotated
    return self.render(context)
  File "C:\Users\el\.virtualenvs\epa-dev-Ocuf8svJ\lib\site-packages\django\template\loader_tags.py", line 62, in render
    result = block.nodelist.render(context)
  File "C:\Users\el\.virtualenvs\epa-dev-Ocuf8svJ\lib\site-packages\django\template\base.py", line 938, in render
    bit = node.render_annotated(context)
  File "C:\Users\el\.virtualenvs\epa-dev-Ocuf8svJ\lib\site-packages\django\template\base.py", line 905, in render_annotated
    return self.render(context)
  File "C:\Users\el\.virtualenvs\epa-dev-Ocuf8svJ\lib\site-packages\django\template\defaulttags.py", line 446, in render
    url = reverse(view_name, args=args, kwargs=kwargs, current_app=current_app)
  File "C:\Users\el\.virtualenvs\epa-dev-Ocuf8svJ\lib\site-packages\django\urls\base.py", line 87, in reverse
    return iri_to_uri(resolver._reverse_with_prefix(view, prefix, *args, **kwargs))
  File "C:\Users\el\.virtualenvs\epa-dev-Ocuf8svJ\lib\site-packages\django\urls\resolvers.py", line 685, in _reverse_with_prefix
    raise NoReverseMatch(msg)
django.urls.exceptions.NoReverseMatch: Reverse for 'scenario_upload' with no arguments not found. 1 pattern(s) tried: ['scenario/upload/(?P<proj_id>[0-9]+)$']
2021-03-01 00:01:20 -    ERROR - django.request - Internal Server Error: /asset/create/dso
Traceback (most recent call last):
  File "C:\Users\el\.virtualenvs\epa-dev-Ocuf8svJ\lib\site-packages\django\core\handlers\exception.py", line 47, in inner
    response = get_response(request)
  File "C:\Users\el\.virtualenvs\epa-dev-Ocuf8svJ\lib\site-packages\django\core\handlers\base.py", line 179, in _get_response
    response = wrapped_callback(request, *callback_args, **callback_kwargs)
  File "C:\Users\el\.virtualenvs\epa-dev-Ocuf8svJ\lib\site-packages\django\contrib\auth\decorators.py", line 21, in _wrapped_view
    return view_func(request, *args, **kwargs)
  File "C:\Users\el\.virtualenvs\epa-dev-Ocuf8svJ\lib\site-packages\django\views\decorators\http.py", line 40, in inner
    return func(request, *args, **kwargs)
  File "C:\Users\el\Desktop\icom_project\E-LAND\epa\projects\views.py", line 338, in get_asset_create_form
    [form.fields.pop(field) for field in form.fields if field not in asset_type.asset_fields]
  File "C:\Users\el\Desktop\icom_project\E-LAND\epa\projects\views.py", line 338, in <listcomp>
    [form.fields.pop(field) for field in form.fields if field not in asset_type.asset_fields]
RuntimeError: dictionary changed size during iteration
2021-03-01 00:01:26 -    ERROR - django.request - Internal Server Error: /asset/create/pv_plant
Traceback (most recent call last):
  File "C:\Users\el\.virtualenvs\epa-dev-Ocuf8svJ\lib\site-packages\django\core\handlers\exception.py", line 47, in inner
    response = get_response(request)
  File "C:\Users\el\.virtualenvs\epa-dev-Ocuf8svJ\lib\site-packages\django\core\handlers\base.py", line 179, in _get_response
    response = wrapped_callback(request, *callback_args, **callback_kwargs)
  File "C:\Users\el\.virtualenvs\epa-dev-Ocuf8svJ\lib\site-packages\django\contrib\auth\decorators.py", line 21, in _wrapped_view
    return view_func(request, *args, **kwargs)
  File "C:\Users\el\.virtualenvs\epa-dev-Ocuf8svJ\lib\site-packages\django\views\decorators\http.py", line 40, in inner
    return func(request, *args, **kwargs)
  File "C:\Users\el\Desktop\icom_project\E-LAND\epa\projects\views.py", line 338, in get_asset_create_form
    [form.fields.pop(field) for field in form.fields if field not in asset_type.asset_fields]
  File "C:\Users\el\Desktop\icom_project\E-LAND\epa\projects\views.py", line 338, in <listcomp>
    [form.fields.pop(field) for field in form.fields if field not in asset_type.asset_fields]
RuntimeError: dictionary changed size during iteration
